[30;1m2023-03-05 23:20:14[0m [34;1mINFO    [0m [35mdiscord.client[0m logging in using static token
Traceback (most recent call last):
  File "/opt/homebrew/lib/python3.11/site-packages/discord/http.py", line 801, in static_login
    data = await self.request(Route('GET', '/users/@me'))
           ^^^^^^^^^^^^^^^^^^^^^^^^^^^^^^^^^^^^^^^^^^^^^^
  File "/opt/homebrew/lib/python3.11/site-packages/discord/http.py", line 744, in request
    raise HTTPException(response, data)
discord.errors.HTTPException: 401 Unauthorized (error code: 0): 401: Unauthorized

The above exception was the direct cause of the following exception:

Traceback (most recent call last):
  File "/Users/felipearon/Documents/insper/nlp/nlp-local/chatbot/deploy_bot_discord.py", line 107, in <module>
    client.run('')
  File "/opt/homebrew/lib/python3.11/site-packages/discord/client.py", line 828, in run
    asyncio.run(runner())
  File "/opt/homebrew/Cellar/python@3.11/3.11.2/Frameworks/Python.framework/Versions/3.11/lib/python3.11/asyncio/runners.py", line 190, in run
    return runner.run(main)
           ^^^^^^^^^^^^^^^^
  File "/opt/homebrew/Cellar/python@3.11/3.11.2/Frameworks/Python.framework/Versions/3.11/lib/python3.11/asyncio/runners.py", line 118, in run
    return self._loop.run_until_complete(task)
           ^^^^^^^^^^^^^^^^^^^^^^^^^^^^^^^^^^^
  File "/opt/homebrew/Cellar/python@3.11/3.11.2/Frameworks/Python.framework/Versions/3.11/lib/python3.11/asyncio/base_events.py", line 653, in run_until_complete
    return future.result()
           ^^^^^^^^^^^^^^^
  File "/opt/homebrew/lib/python3.11/site-packages/discord/client.py", line 817, in runner
    await self.start(token, reconnect=reconnect)
  File "/opt/homebrew/lib/python3.11/site-packages/discord/client.py", line 745, in start
    await self.login(token)
  File "/opt/homebrew/lib/python3.11/site-packages/discord/client.py", line 580, in login
    data = await self.http.static_login(token)
           ^^^^^^^^^^^^^^^^^^^^^^^^^^^^^^^^^^^
  File "/opt/homebrew/lib/python3.11/site-packages/discord/http.py", line 805, in static_login
    raise LoginFailure('Improper token has been passed.') from exc
discord.errors.LoginFailure: Improper token has been passed.
[30;1m2023-03-05 23:20:32[0m [34;1mINFO    [0m [35mdiscord.client[0m logging in using static token
Traceback (most recent call last):
  File "/opt/homebrew/lib/python3.11/site-packages/discord/http.py", line 801, in static_login
    data = await self.request(Route('GET', '/users/@me'))
           ^^^^^^^^^^^^^^^^^^^^^^^^^^^^^^^^^^^^^^^^^^^^^^
  File "/opt/homebrew/lib/python3.11/site-packages/discord/http.py", line 744, in request
    raise HTTPException(response, data)
discord.errors.HTTPException: 401 Unauthorized (error code: 0): 401: Unauthorized

The above exception was the direct cause of the following exception:

Traceback (most recent call last):
  File "/Users/felipearon/Documents/insper/nlp/nlp-local/chatbot/deploy_bot_discord.py", line 107, in <module>
    client.run('!run check_symbol_last_trade_price_and_quantity BTCUSDT')
  File "/opt/homebrew/lib/python3.11/site-packages/discord/client.py", line 828, in run
    asyncio.run(runner())
  File "/opt/homebrew/Cellar/python@3.11/3.11.2/Frameworks/Python.framework/Versions/3.11/lib/python3.11/asyncio/runners.py", line 190, in run
    return runner.run(main)
           ^^^^^^^^^^^^^^^^
  File "/opt/homebrew/Cellar/python@3.11/3.11.2/Frameworks/Python.framework/Versions/3.11/lib/python3.11/asyncio/runners.py", line 118, in run
    return self._loop.run_until_complete(task)
           ^^^^^^^^^^^^^^^^^^^^^^^^^^^^^^^^^^^
  File "/opt/homebrew/Cellar/python@3.11/3.11.2/Frameworks/Python.framework/Versions/3.11/lib/python3.11/asyncio/base_events.py", line 653, in run_until_complete
    return future.result()
           ^^^^^^^^^^^^^^^
  File "/opt/homebrew/lib/python3.11/site-packages/discord/client.py", line 817, in runner
    await self.start(token, reconnect=reconnect)
  File "/opt/homebrew/lib/python3.11/site-packages/discord/client.py", line 745, in start
    await self.login(token)
  File "/opt/homebrew/lib/python3.11/site-packages/discord/client.py", line 580, in login
    data = await self.http.static_login(token)
           ^^^^^^^^^^^^^^^^^^^^^^^^^^^^^^^^^^^
  File "/opt/homebrew/lib/python3.11/site-packages/discord/http.py", line 805, in static_login
    raise LoginFailure('Improper token has been passed.') from exc
discord.errors.LoginFailure: Improper token has been passed.
[30;1m2023-03-05 23:20:59[0m [34;1mINFO    [0m [35mdiscord.client[0m logging in using static token
[30;1m2023-03-05 23:21:00[0m [34;1mINFO    [0m [35mdiscord.gateway[0m Shard ID None has connected to Gateway (Session ID: de2cc98c31df18ecafec7282c7d1a743).
